<?xml version="1.0"?>
<robot name="logistics_robot" xmlns:xacro="http://www.ros.org/wiki/xacro">

  <material name="dark_grey">
    <color rgba="0.2 0.2 0.2 1.0"/>
  </material>
  <material name="light_grey">
    <color rgba="0.7 0.7 0.7 1.0"/>
  </material>
  <material name="orange">
    <color rgba="1.0 0.5 0.0 1.0"/>
  </material>
  <material name="white">
    <color rgba="1.0 1.0 1.0 1.0"/>
  </material>
  <material name="black">
    <color rgba="0.05 0.05 0.05 1.0"/>
  </material>
  <material name="blue">
    <color rgba="0.0 0.4 0.8 1.0"/>
  </material>
  <material name="yellow">
    <color rgba="1.0 0.9 0.0 1.0"/>
  </material>

  <link name="base_footprint"/>

  <joint name="base_joint" type="fixed">
    <parent link="base_footprint"/>
    <child link="base_link"/>
    <origin xyz="0 0 0.1" rpy="0 0 0"/>
  </joint>

  <link name="base_link">
    <visual>
      <origin xyz="0 0 0" rpy="0 0 0"/>
      <geometry>
        <box size="0.35 0.25 0.08"/>
      </geometry>
      <material name="dark_grey"/>
    </visual>
    <collision>
      <origin xyz="0 0 0" rpy="0 0 0"/>
      <geometry>
        <box size="0.35 0.25 0.08"/>
      </geometry>
    </collision>
    <inertial>
      <mass value="5.0"/>
      <origin xyz="0 0 0" rpy="0 0 0"/>
      <inertia ixx="0.0633" ixy="0" ixz="0"
               iyy="0.1083" iyz="0"
               izz="0.1583"/>
    </inertial>
  </link>

  <link name="top_plate">
    <visual>
      <origin xyz="0 0 0" rpy="0 0 0"/>
      <geometry>
        <box size="0.30 0.22 0.02"/>
      </geometry>
      <material name="orange"/>
    </visual>
    <collision>
      <origin xyz="0 0 0"/>
      <geometry>
        <box size="0.30 0.22 0.02"/>
      </geometry>
    </collision>
    <inertial>
      <mass value="0.5"/>
      <inertia ixx="0.001" ixy="0" ixz="0" iyy="0.001" iyz="0" izz="0.001"/>
    </inertial>
  </link>

  <joint name="top_plate_joint" type="fixed">
    <parent link="base_link"/>
    <child link="top_plate"/>
    <origin xyz="0 0 0.05" rpy="0 0 0"/>
  </joint>

  <link name="sensor_tower">
    <visual>
      <origin xyz="0 0 0" rpy="0 0 0"/>
      <geometry>
        <cylinder radius="0.04" length="0.12"/>
      </geometry>
      <material name="light_grey"/>
    </visual>
    <inertial>
      <mass value="0.3"/>
      <inertia ixx="0.001" ixy="0" ixz="0" iyy="0.001" iyz="0" izz="0.001"/>
    </inertial>
  </link>

  <joint name="sensor_tower_joint" type="fixed">
    <parent link="top_plate"/>
    <child link="sensor_tower"/>
    <origin xyz="0.05 0 0.07" rpy="0 0 0"/>
  </joint>

  <link name="lidar_link">
    <visual>
      <origin xyz="0 0 0" rpy="0 0 0"/>
      <geometry>
        <cylinder radius="0.035" length="0.04"/>
      </geometry>
      <material name="black"/>
    </visual>
    <collision>
      <geometry>
        <cylinder radius="0.035" length="0.04"/>
      </geometry>
    </collision>
    <inertial>
      <mass value="0.1"/>
      <inertia ixx="0.0001" ixy="0" ixz="0" iyy="0.0001" iyz="0" izz="0.0001"/>
    </inertial>
  </link>

  <joint name="lidar_joint" type="fixed">
    <parent link="sensor_tower"/>
    <child link="lidar_link"/>
    <origin xyz="0 0 0.08" rpy="0 0 0"/>
  </joint>

  <link name="camera_link">
    <visual>
      <origin xyz="0 0 0" rpy="0 0 0"/>
      <geometry>
        <box size="0.025 0.09 0.025"/>
      </geometry>
      <material name="black"/>
    </visual>
    <inertial>
      <mass value="0.05"/>
      <inertia ixx="0.0001" ixy="0" ixz="0" iyy="0.0001" iyz="0" izz="0.0001"/>
    </inertial>
  </link>

  <joint name="camera_joint" type="fixed">
    <parent link="sensor_tower"/>
    <child link="camera_link"/>
    <origin xyz="0.04 0 0.04" rpy="0 0 0"/>
  </joint>

  <link name="left_wheel">
    <visual>
      <origin xyz="0 0 0" rpy="1.5707963 0 0"/>
      <geometry>
        <cylinder radius="0.07" length="0.04"/>
      </geometry>
      <material name="black"/>
    </visual>
    <collision>
      <origin xyz="0 0 0" rpy="1.5707963 0 0"/>
      <geometry>
        <cylinder radius="0.07" length="0.04"/>
      </geometry>
    </collision>
    <inertial>
      <mass value="0.5"/>
      <origin xyz="0 0 0" rpy="1.5707963 0 0"/>
      <inertia ixx="0.0008" ixy="0" ixz="0"
               iyy="0.0008" iyz="0"
               izz="0.0012"/>
    </inertial>
  </link>

  <joint name="left_wheel_joint" type="continuous">
    <parent link="base_link"/>
    <child link="left_wheel"/>
    <origin xyz="0 0.145 -0.03" rpy="0 0 0"/>
    <axis xyz="0 1 0"/>
  </joint>

  <!-- ==================== RIGHT WHEEL ==================== -->
  <link name="right_wheel">
    <visual>
      <origin xyz="0 0 0" rpy="1.5707963 0 0"/>
      <geometry>
        <cylinder radius="0.07" length="0.04"/>
      </geometry>
      <material name="black"/>
    </visual>
    <collision>
      <origin xyz="0 0 0" rpy="1.5707963 0 0"/>
      <geometry>
        <cylinder radius="0.07" length="0.04"/>
      </geometry>
    </collision>
    <inertial>
      <mass value="0.5"/>
      <origin xyz="0 0 0" rpy="1.5707963 0 0"/>
      <inertia ixx="0.0008" ixy="0" ixz="0"
               iyy="0.0008" iyz="0"
               izz="0.0012"/>
    </inertial>
  </link>

  <joint name="right_wheel_joint" type="continuous">
    <parent link="base_link"/>
    <child link="right_wheel"/>
    <origin xyz="0 -0.145 -0.03" rpy="0 0 0"/>
    <axis xyz="0 1 0"/>
  </joint>

  <link name="front_caster">
    <visual>
      <geometry>
        <sphere radius="0.025"/>
      </geometry>
      <material name="light_grey"/>
    </visual>
    <collision>
      <geometry>
        <sphere radius="0.025"/>
      </geometry>
    </collision>
    <inertial>
      <mass value="0.1"/>
      <inertia ixx="0.00001" ixy="0" ixz="0" iyy="0.00001" iyz="0" izz="0.00001"/>
    </inertial>
  </link>

  <joint name="front_caster_joint" type="fixed">
    <parent link="base_link"/>
    <child link="front_caster"/>
    <origin xyz="0.15 0 -0.055" rpy="0 0 0"/>
  </joint>

  <link name="rear_caster">
    <visual>
      <geometry>
        <sphere radius="0.025"/>
      </geometry>
      <material name="light_grey"/>
    </visual>
    <collision>
      <geometry>
        <sphere radius="0.025"/>
      </geometry>
    </collision>
    <inertial>
      <mass value="0.1"/>
      <inertia ixx="0.00001" ixy="0" ixz="0" iyy="0.00001" iyz="0" izz="0.00001"/>
    </inertial>
  </link>

  <joint name="rear_caster_joint" type="fixed">
    <parent link="base_link"/>
    <child link="rear_caster"/>
    <origin xyz="-0.15 0 -0.055" rpy="0 0 0"/>
  </joint>

  <link name="arm_base">
    <visual>
      <origin xyz="0 0 0" rpy="0 0 0"/>
      <geometry>
        <box size="0.06 0.06 0.05"/>
      </geometry>
      <material name="blue"/>
    </visual>
    <inertial>
      <mass value="0.3"/>
      <inertia ixx="0.001" ixy="0" ixz="0" iyy="0.001" iyz="0" izz="0.001"/>
    </inertial>
  </link>

  <joint name="arm_base_joint" type="fixed">
    <parent link="top_plate"/>
    <child link="arm_base"/>
    <origin xyz="-0.08 0 0.035" rpy="0 0 0"/>
  </joint>

  <link name="arm_shoulder">
    <visual>
      <origin xyz="0 0 0.055" rpy="0 0 0"/>
      <geometry>
        <cylinder radius="0.02" length="0.11"/>
      </geometry>
      <material name="blue"/>
    </visual>
    <inertial>
      <mass value="0.2"/>
      <inertia ixx="0.001" ixy="0" ixz="0" iyy="0.001" iyz="0" izz="0.001"/>
    </inertial>
  </link>

  <joint name="shoulder_joint" type="revolute">
    <parent link="arm_base"/>
    <child link="arm_shoulder"/>
    <origin xyz="0 0 0.05" rpy="0 0 0"/>
    <axis xyz="0 1 0"/>
    <limit lower="-1.57" upper="1.57" effort="10.0" velocity="1.0"/>
  </joint>

  <link name="arm_forearm">
    <visual>
      <origin xyz="0 0 0.055" rpy="0 0 0"/>
      <geometry>
        <cylinder radius="0.018" length="0.11"/>
      </geometry>
      <material name="light_grey"/>
    </visual>
    <inertial>
      <mass value="0.15"/>
      <inertia ixx="0.0005" ixy="0" ixz="0" iyy="0.0005" iyz="0" izz="0.0005"/>
    </inertial>
  </link>

  <joint name="elbow_joint" type="revolute">
    <parent link="arm_shoulder"/>
    <child link="arm_forearm"/>
    <origin xyz="0 0 0.11" rpy="0 0 0"/>
    <axis xyz="0 1 0"/>
    <limit lower="-1.57" upper="1.57" effort="8.0" velocity="1.0"/>
  </joint>

  <link name="gripper_base">
    <visual>
      <origin xyz="0 0 0" rpy="0 0 0"/>
      <geometry>
        <box size="0.06 0.05 0.03"/>
      </geometry>
      <material name="dark_grey"/>
    </visual>
    <inertial>
      <mass value="0.1"/>
      <inertia ixx="0.0001" ixy="0" ixz="0" iyy="0.0001" iyz="0" izz="0.0001"/>
    </inertial>
  </link>

  <joint name="wrist_joint" type="revolute">
    <parent link="arm_forearm"/>
    <child link="gripper_base"/>
    <origin xyz="0 0 0.11" rpy="0 0 0"/>
    <axis xyz="0 0 1"/>
    <limit lower="-3.14" upper="3.14" effort="5.0" velocity="2.0"/>
  </joint>

  <link name="left_finger">
    <visual>
      <origin xyz="0 0 0.02" rpy="0 0 0"/>
      <geometry>
        <box size="0.01 0.015 0.04"/>
      </geometry>
      <material name="yellow"/>
    </visual>
    <inertial>
      <mass value="0.02"/>
      <inertia ixx="0.00001" ixy="0" ixz="0" iyy="0.00001" iyz="0" izz="0.00001"/>
    </inertial>
  </link>

  <joint name="left_finger_joint" type="prismatic">
    <parent link="gripper_base"/>
    <child link="left_finger"/>
    <origin xyz="0.02 0.02 0.015" rpy="0 0 0"/>
    <axis xyz="0 1 0"/>
    <limit lower="0" upper="0.03" effort="3.0" velocity="0.5"/>
  </joint>

  <link name="right_finger">
    <visual>
      <origin xyz="0 0 0.02" rpy="0 0 0"/>
      <geometry>
        <box size="0.01 0.015 0.04"/>
      </geometry>
      <material name="yellow"/>
    </visual>
    <inertial>
      <mass value="0.02"/>
      <inertia ixx="0.00001" ixy="0" ixz="0" iyy="0.00001" iyz="0" izz="0.00001"/>
    </inertial>
  </link>

  <joint name="right_finger_joint" type="prismatic">
    <parent link="gripper_base"/>
    <child link="right_finger"/>
    <origin xyz="0.02 -0.02 0.015" rpy="0 0 0"/>
    <axis xyz="0 -1 0"/>
    <limit lower="0" upper="0.03" effort="3.0" velocity="0.5"/>
  </joint>

</robot>
